<?xml version="1.0" encoding="utf-8"?>
<testsuite name="nosetests" tests="3" errors="0" failures="1"
skip="0">
  <testcase classname="test_xunit" name="test_add" time="0.000" />
  <testcase classname="test_xunit" name="test_sub" time="0.000" />
  <testcase classname="test_xunit" name="test_sub_fail"
  time="0.000">
    <failure type="exceptions.AssertionError" message="bad sub">
      <![CDATA[Traceback (most recent call last):
  File "/usr/lib/python2.7/unittest/case.py", line 327, in run
    testMethod()
  File "/usr/local/lib/python2.7/dist-packages/nose/case.py", line 197, in runTest
    self.test(*self.arg)
  File "/home/miki/Projects/goroot/src/xunit/test_xunit.py", line 8, in test_sub_fail
    assert 2 - 2 == 1, "bad sub"
AssertionError: bad sub
]]>
</failure>
  </testcase>
</testsuite>
